Traceback (most recent call last):
  File "/usr/local/lib/python3.10/dist-packages/torch/distributed/run.py", line 677, in determine_local_world_size
    return int(nproc_per_node)
ValueError: invalid literal for int() with base 10: ''

The above exception was the direct cause of the following exception:

Traceback (most recent call last):
  File "/usr/local/bin/torchrun", line 33, in <module>
    sys.exit(load_entry_point('torch==2.5.0a0+e000cf0ad9.nv24.10', 'console_scripts', 'torchrun')())
  File "/usr/local/lib/python3.10/dist-packages/torch/distributed/elastic/multiprocessing/errors/__init__.py", line 355, in wrapper
    return f(*args, **kwargs)
  File "/usr/local/lib/python3.10/dist-packages/torch/distributed/run.py", line 919, in main
    run(args)
  File "/usr/local/lib/python3.10/dist-packages/torch/distributed/run.py", line 909, in run
    config, cmd, cmd_args = config_from_args(args)
  File "/usr/local/lib/python3.10/dist-packages/torch/distributed/run.py", line 790, in config_from_args
    nproc_per_node = determine_local_world_size(args.nproc_per_node)
  File "/usr/local/lib/python3.10/dist-packages/torch/distributed/run.py", line 706, in determine_local_world_size
    raise ValueError(
ValueError: Unsupported nproc_per_node value: 
DONE!
