/usr/local/lib/python3.10/dist-packages/torchvision/models/_utils.py:208: UserWarning: The parameter 'pretrained' is deprecated since 0.13 and may be removed in the future, please use 'weights' instead.
  warnings.warn(
/usr/local/lib/python3.10/dist-packages/torchvision/models/_utils.py:223: UserWarning: Arguments other than a weight enum or `None` for 'weights' are deprecated since 0.13 and may be removed in the future. The current behavior is equivalent to passing `weights=ResNet50_Weights.IMAGENET1K_V1`. You can also use `weights=ResNet50_Weights.DEFAULT` to get the most up-to-date weights.
  warnings.warn(msg)
NOTE! Installing ujson may make loading annotations faster.
DLL 2024-11-01 00:18:16.355958 - PARAMETER dataset path : /data/object_detection  epochs : 1  batch size : 480  eval batch size : 32  no cuda : False  seed : None  checkpoint path : None  mode : benchmark-training  eval on epochs : [21, 31, 37, 42, 48, 53, 59, 64]  lr decay epochs : [43, 54]  learning rate : 0.0  momentum : 0.9  weight decay : 0.0005  lr warmup : None  backbone : resnet50  backbone path : None  num workers : 64  AMP : True  precision : amp 
Using seed = 5960
Loading annotations into memory...
Traceback (most recent call last):
  File "/workspace/benchmark/Detection/SSD/main.py", line 286, in <module>
    train(train_loop_func, logger, args)
  File "/workspace/benchmark/Detection/SSD/main.py", line 146, in train
    cocoGt = get_coco_ground_truth(args)
  File "/workspace/benchmark/Detection/SSD/ssd/data.py", line 73, in get_coco_ground_truth
    cocoGt = COCO(annotation_file=val_annotate, use_ext=True)
  File "/usr/local/lib/python3.10/dist-packages/pycocotools/coco.py", line 122, in __init__
    dataset = json.load(open(annotation_file, 'r'))
FileNotFoundError: [Errno 2] No such file or directory: '/data/object_detection/annotations/instances_val2017.json'
[2024-11-01 00:18:19,378] torch.distributed.elastic.multiprocessing.api: [ERROR] failed (exitcode: 1) local_rank: 0 (pid: 5761) of binary: /usr/bin/python
Traceback (most recent call last):
  File "/usr/local/bin/torchrun", line 8, in <module>
    sys.exit(main())
  File "/usr/local/lib/python3.10/dist-packages/torch/distributed/elastic/multiprocessing/errors/__init__.py", line 347, in wrapper
    return f(*args, **kwargs)
  File "/usr/local/lib/python3.10/dist-packages/torch/distributed/run.py", line 834, in main
    run(args)
  File "/usr/local/lib/python3.10/dist-packages/torch/distributed/run.py", line 825, in run
    elastic_launch(
  File "/usr/local/lib/python3.10/dist-packages/torch/distributed/launcher/api.py", line 137, in __call__
    return launch_agent(self._config, self._entrypoint, list(args))
  File "/usr/local/lib/python3.10/dist-packages/torch/distributed/launcher/api.py", line 271, in launch_agent
    raise ChildFailedError(
torch.distributed.elastic.multiprocessing.errors.ChildFailedError: 
============================================================
main.py FAILED
------------------------------------------------------------
Failures:
  <NO_OTHER_FAILURES>
------------------------------------------------------------
Root Cause (first observed failure):
[0]:
  time      : 2024-11-01_00:18:19
  host      : 1c464adf3711
  rank      : 0 (local_rank: 0)
  exitcode  : 1 (pid: 5761)
  error_file: <N/A>
  traceback : To enable traceback see: https://pytorch.org/docs/stable/elastic/errors.html
============================================================
DONE!
